<?xml version='1.0' encoding='ASCII'?>
<sdf version="1.4">
  <model name="tigrillo">
    <static>False</static>
    <self_collide>False</self_collide>
    <link name="body_front">
      <pose>0 0.08 0.185 0 0 0</pose>
      <inertial>
        <mass>0.3</mass>
        <inertia>
          <ixx>0.0001825</ixx>
          <ixy>0</ixy>
          <ixz>0</ixz>
          <iyy>0.0005125</iyy>
          <iyz>0</iyz>
          <izz>0.00065</izz>
        </inertia>
      </inertial>
      <collision name="body_frontcol">
        <geometry>
          <box>
            <size>0.14 0.08 0.03</size>
          </box>
        </geometry>
      </collision>
      <visual name="body_frontvis">
        <pose>0 0.018 -0.018 0 0 -1.57079632679</pose>
        <geometry>
          <mesh>
            <uri>model://tigrillo/meshes/front.dae</uri>
            <scale>0.001 0.001 0.001</scale>
          </mesh>
        </geometry>
        <material>
          <script>
            <uri>file://media/materials/scripts/gazebo.material</uri>
            <name>Gazebo/Orange</name>
          </script>
        </material>
      </visual>
    </link>
    <link name="body_middle">
      <pose>0 0 0.17125 0 0 0</pose>
      <inertial>
        <mass>0.03</mass>
        <inertia>
          <ixx>1.6015625e-05</ixx>
          <ixy>0</ixy>
          <ixz>0</ixz>
          <iyy>6.265625e-06</iyy>
          <iyz>0</iyz>
          <izz>2.225e-05</izz>
        </inertia>
      </inertial>
      <collision name="body_middlecol">
        <geometry>
          <box>
            <size>0.05 0.08 0.0025</size>
          </box>
        </geometry>
      </collision>
      <visual name="body_middlevis">
        <pose>0 0 -0.004 0 0 -1.57079632679</pose>
        <geometry>
          <mesh>
            <uri>model://tigrillo/meshes/middle.dae</uri>
            <scale>0.001 0.001 0.001</scale>
          </mesh>
        </geometry>
        <material>
          <script>
            <uri>file://media/materials/scripts/gazebo.material</uri>
            <name>Gazebo/FlatBlack</name>
          </script>
        </material>
      </visual>
    </link>
    <link name="body_hind">
      <pose>0 -0.07 0.1825 0 0 0</pose>
      <inertial>
        <mass>0.1</mass>
        <inertia>
          <ixx>3.52083333333e-05</ixx>
          <ixy>0</ixy>
          <ixz>0</ixz>
          <iyy>7.27083333333e-05</iyy>
          <iyz>0</iyz>
          <izz>9.75e-05</izz>
        </inertia>
      </inertial>
      <collision name="body_hindcol">
        <geometry>
          <box>
            <size>0.09 0.06 0.025</size>
          </box>
        </geometry>
      </collision>
      <visual name="body_hindvis">
        <pose>0 0 -0.016 0 0 -1.57079632679</pose>
        <geometry>
          <mesh>
            <uri>model://tigrillo/meshes/hind.dae</uri>
            <scale>0.001 0.0009 0.001</scale>
          </mesh>
        </geometry>
        <material>
          <script>
            <uri>file://media/materials/scripts/gazebo.material</uri>
            <name>Gazebo/Orange</name>
          </script>
        </material>
      </visual>
    </link>
    <link name="BLM">
      <pose>-0.027 -0.07 0.1447 0 0 0</pose>
      <inertial>
        <mass>0.067</mass>
        <inertia>
          <ixx>2.15313433333e-05</ixx>
          <ixy>0</ixy>
          <ixz>0</ixz>
          <iyy>2.15313433333e-05</iyy>
          <iyz>0</iyz>
          <izz>1.4472e-05</izz>
        </inertia>
      </inertial>
      <collision name="BLM_col">
        <geometry>
          <box>
            <size>0.036 0.036 0.0506</size>
          </box>
        </geometry>
      </collision>
      <visual name="BLM_vis">
        <pose>0 0 0 -1.57079632679 0 1.57079632679</pose>
        <geometry>
          <mesh>
            <uri>model://tigrillo/meshes/motor.dae</uri>
            <scale>0.001 0.001 0.001</scale>
          </mesh>
        </geometry>
        <material>
          <script>
            <uri>file://media/materials/scripts/gazebo.material</uri>
            <name>Gazebo/Orange</name>
          </script>
        </material>
      </visual>
    </link>
    <link name="BLU">
      <pose>-0.0495 -0.07 0.137 0.00436332312999 0 0</pose>
      <inertial>
        <pose>0 0 -0.035 0 0 0</pose>
        <mass>0.351858377202</mass>
        <inertia>
          <ixx>0.000145082937533</ixx>
          <ixy>0</ixy>
          <ixz>0</ixz>
          <iyy>0.000145082937533</iyy>
          <iyz>0</iyz>
          <izz>2.81486701762e-06</izz>
        </inertia>
      </inertial>
      <collision name="BLU_col">
        <pose>0 0 -0.035 0 0 0</pose>
        <geometry>
          <cylinder>
            <radius>0.004</radius>
            <length>0.07</length>
          </cylinder>
        </geometry>
      </collision>
      <visual name="BLU_vis">
        <pose>-0.0040 0 0 0 1.57079632679 0</pose>
        <geometry>
          <mesh>
            <uri>model://tigrillo/meshes/femur.dae</uri>
            <scale>0.001 0.001 0.001</scale>
          </mesh>
        </geometry>
        <material>
          <script>
            <uri>file://media/materials/scripts/gazebo.material</uri>
            <name>Gazebo/Turquoise</name>
          </script>
        </material>
      </visual>
    </link>
    <link name="BLD">
      <pose>-0.0495 -0.0696945683501 0.0670006663495 0.590048866587 0 0</pose>
      <inertial>
        <pose>0 0 -0.01 0 0 0</pose>
        <mass>0.452389342117</mass>
        <inertia>
          <ixx>0.000307172363297</ixx>
          <ixy>0</ixy>
          <ixz>0</ixz>
          <iyy>0.000307172363297</iyy>
          <iyz>0</iyz>
          <izz>3.61911473694e-06</izz>
        </inertia>
      </inertial>
      <collision name="BLDT_col">
        <pose>0 0 -0.01 0 0 0</pose>
        <geometry>
          <cylinder>
            <radius>0.004</radius>
            <length>0.09</length>
          </cylinder>
        </geometry>
      </collision>
      <visual name="BLDT_vis">
        <pose>0.004 0 -0.048-1.57079632679 0 1.57079632679</pose>
        <geometry>
          <mesh>
            <uri>model://tigrillo/meshes/tibia.dae</uri>
            <scale>0.001 0.001 0.001</scale>
          </mesh>
        </geometry>
        <material>
          <script>
            <name>Gazebo/Turquoise</name>
            <uri>file://media/materials/scripts/gazebo.material</uri>
          </script>
        </material>
      </visual>
      <collision name="BLDF_col">
        <pose> 0 0 -0.055 0 0 0</pose>
        <geometry>
          <sphere>
            <radius>0.006</radius>
          </sphere>
        </geometry>
        <surface>
          <friction>
            <ode>
              <mu>15000</mu>
              <mu2>15000</mu2>
            </ode>
          </friction>
          <contact>
            <ode>
              <min_depth>0.0005</min_depth>
            </ode>
          </contact>
        </surface>
      </collision>
    </link>
    <link name="FRM">
      <pose>0.052 0.08 0.1447 0 0 0</pose>
      <inertial>
        <mass>0.067</mass>
        <inertia>
          <ixx>2.15313433333e-05</ixx>
          <ixy>0</ixy>
          <ixz>0</ixz>
          <iyy>2.15313433333e-05</iyy>
          <iyz>0</iyz>
          <izz>1.4472e-05</izz>
        </inertia>
      </inertial>
      <collision name="FRM_col">
        <geometry>
          <box>
            <size>0.036 0.036 0.0506</size>
          </box>
        </geometry>
      </collision>
      <visual name="FRM_vis">
        <pose>0 0 0 -1.57079632679 0 -1.57079632679</pose>
        <geometry>
          <mesh>
            <uri>model://tigrillo/meshes/motor.dae</uri>
            <scale>0.001 0.001 0.001</scale>
          </mesh>
        </geometry>
        <material>
          <script>
            <uri>file://media/materials/scripts/gazebo.material</uri>
            <name>Gazebo/Orange</name>
          </script>
        </material>
      </visual>
    </link>
    <link name="FRU">
      <pose>0.0745 0.08 0.137 0.00436332312999 0 0</pose>
      <inertial>
        <pose>0 0 -0.035 0 0 0</pose>
        <mass>0.351858377202</mass>
        <inertia>
          <ixx>0.000145082937533</ixx>
          <ixy>0</ixy>
          <ixz>0</ixz>
          <iyy>0.000145082937533</iyy>
          <iyz>0</iyz>
          <izz>2.81486701762e-06</izz>
        </inertia>
      </inertial>
      <collision name="FRU_col">
        <pose>0 0 -0.035 0 0 0</pose>
        <geometry>
          <cylinder>
            <radius>0.004</radius>
            <length>0.07</length>
          </cylinder>
        </geometry>
      </collision>
      <visual name="FRU_vis">
        <pose>-0.0040 0 0 0 1.57079632679 0</pose>
        <geometry>
          <mesh>
            <uri>model://tigrillo/meshes/femur.dae</uri>
            <scale>0.001 0.001 0.001</scale>
          </mesh>
        </geometry>
        <material>
          <script>
            <uri>file://media/materials/scripts/gazebo.material</uri>
            <name>Gazebo/Turquoise</name>
          </script>
        </material>
      </visual>
    </link>
    <link name="FRD">
      <pose>0.0745 0.0803054316499 0.0670006663495 0.590048866587 0 0</pose>
      <inertial>
        <pose>0 0 -0.01 0 0 0</pose>
        <mass>0.452389342117</mass>
        <inertia>
          <ixx>0.000307172363297</ixx>
          <ixy>0</ixy>
          <ixz>0</ixz>
          <iyy>0.000307172363297</iyy>
          <iyz>0</iyz>
          <izz>3.61911473694e-06</izz>
        </inertia>
      </inertial>
      <collision name="FRDT_col">
        <pose>0 0 -0.01 0 0 0</pose>
        <geometry>
          <cylinder>
            <radius>0.004</radius>
            <length>0.09</length>
          </cylinder>
        </geometry>
      </collision>
      <visual name="FRDT_vis">
        <pose>0.004 0 -0.048-1.57079632679 0 1.57079632679</pose>
        <geometry>
          <mesh>
            <uri>model://tigrillo/meshes/tibia.dae</uri>
            <scale>0.001 0.001 0.001</scale>
          </mesh>
        </geometry>
        <material>
          <script>
            <name>Gazebo/Turquoise</name>
            <uri>file://media/materials/scripts/gazebo.material</uri>
          </script>
        </material>
      </visual>
      <collision name="FRDF_col">
        <pose> 0 0 -0.055 0 0 0</pose>
        <geometry>
          <sphere>
            <radius>0.006</radius>
          </sphere>
        </geometry>
        <surface>
          <friction>
            <ode>
              <mu>15000</mu>
              <mu2>15000</mu2>
            </ode>
          </friction>
          <contact>
            <ode>
              <min_depth>0.0005</min_depth>
            </ode>
          </contact>
        </surface>
      </collision>
    </link>
    <link name="FLM">
      <pose>-0.052 0.08 0.1447 0 0 0</pose>
      <inertial>
        <mass>0.067</mass>
        <inertia>
          <ixx>2.15313433333e-05</ixx>
          <ixy>0</ixy>
          <ixz>0</ixz>
          <iyy>2.15313433333e-05</iyy>
          <iyz>0</iyz>
          <izz>1.4472e-05</izz>
        </inertia>
      </inertial>
      <collision name="FLM_col">
        <geometry>
          <box>
            <size>0.036 0.036 0.0506</size>
          </box>
        </geometry>
      </collision>
      <visual name="FLM_vis">
        <pose>0 0 0 -1.57079632679 0 1.57079632679</pose>
        <geometry>
          <mesh>
            <uri>model://tigrillo/meshes/motor.dae</uri>
            <scale>0.001 0.001 0.001</scale>
          </mesh>
        </geometry>
        <material>
          <script>
            <uri>file://media/materials/scripts/gazebo.material</uri>
            <name>Gazebo/Orange</name>
          </script>
        </material>
      </visual>
    </link>
    <link name="FLU">
      <pose>-0.0745 0.08 0.137 0.00436332312999 0 0</pose>
      <inertial>
        <pose>0 0 -0.035 0 0 0</pose>
        <mass>0.351858377202</mass>
        <inertia>
          <ixx>0.000145082937533</ixx>
          <ixy>0</ixy>
          <ixz>0</ixz>
          <iyy>0.000145082937533</iyy>
          <iyz>0</iyz>
          <izz>2.81486701762e-06</izz>
        </inertia>
      </inertial>
      <collision name="FLU_col">
        <pose>0 0 -0.035 0 0 0</pose>
        <geometry>
          <cylinder>
            <radius>0.004</radius>
            <length>0.07</length>
          </cylinder>
        </geometry>
      </collision>
      <visual name="FLU_vis">
        <pose>-0.0040 0 0 0 1.57079632679 0</pose>
        <geometry>
          <mesh>
            <uri>model://tigrillo/meshes/femur.dae</uri>
            <scale>0.001 0.001 0.001</scale>
          </mesh>
        </geometry>
        <material>
          <script>
            <uri>file://media/materials/scripts/gazebo.material</uri>
            <name>Gazebo/Turquoise</name>
          </script>
        </material>
      </visual>
    </link>
    <link name="FLD">
      <pose>-0.0745 0.0803054316499 0.0670006663495 0.590048866587 0 0</pose>
      <inertial>
        <pose>0 0 -0.01 0 0 0</pose>
        <mass>0.452389342117</mass>
        <inertia>
          <ixx>0.000307172363297</ixx>
          <ixy>0</ixy>
          <ixz>0</ixz>
          <iyy>0.000307172363297</iyy>
          <iyz>0</iyz>
          <izz>3.61911473694e-06</izz>
        </inertia>
      </inertial>
      <collision name="FLDT_col">
        <pose>0 0 -0.01 0 0 0</pose>
        <geometry>
          <cylinder>
            <radius>0.004</radius>
            <length>0.09</length>
          </cylinder>
        </geometry>
      </collision>
      <visual name="FLDT_vis">
        <pose>0.004 0 -0.048-1.57079632679 0 1.57079632679</pose>
        <geometry>
          <mesh>
            <uri>model://tigrillo/meshes/tibia.dae</uri>
            <scale>0.001 0.001 0.001</scale>
          </mesh>
        </geometry>
        <material>
          <script>
            <name>Gazebo/Turquoise</name>
            <uri>file://media/materials/scripts/gazebo.material</uri>
          </script>
        </material>
      </visual>
      <collision name="FLDF_col">
        <pose> 0 0 -0.055 0 0 0</pose>
        <geometry>
          <sphere>
            <radius>0.006</radius>
          </sphere>
        </geometry>
        <surface>
          <friction>
            <ode>
              <mu>15000</mu>
              <mu2>15000</mu2>
            </ode>
          </friction>
          <contact>
            <ode>
              <min_depth>0.0005</min_depth>
            </ode>
          </contact>
        </surface>
      </collision>
    </link>
    <link name="BRM">
      <pose>0.027 -0.07 0.1447 0 0 0</pose>
      <inertial>
        <mass>0.067</mass>
        <inertia>
          <ixx>2.15313433333e-05</ixx>
          <ixy>0</ixy>
          <ixz>0</ixz>
          <iyy>2.15313433333e-05</iyy>
          <iyz>0</iyz>
          <izz>1.4472e-05</izz>
        </inertia>
      </inertial>
      <collision name="BRM_col">
        <geometry>
          <box>
            <size>0.036 0.036 0.0506</size>
          </box>
        </geometry>
      </collision>
      <visual name="BRM_vis">
        <pose>0 0 0 -1.57079632679 0 -1.57079632679</pose>
        <geometry>
          <mesh>
            <uri>model://tigrillo/meshes/motor.dae</uri>
            <scale>0.001 0.001 0.001</scale>
          </mesh>
        </geometry>
        <material>
          <script>
            <uri>file://media/materials/scripts/gazebo.material</uri>
            <name>Gazebo/Orange</name>
          </script>
        </material>
      </visual>
    </link>
    <link name="BRU">
      <pose>0.0495 -0.07 0.137 0.00436332312999 0 0</pose>
      <inertial>
        <pose>0 0 -0.035 0 0 0</pose>
        <mass>0.351858377202</mass>
        <inertia>
          <ixx>0.000145082937533</ixx>
          <ixy>0</ixy>
          <ixz>0</ixz>
          <iyy>0.000145082937533</iyy>
          <iyz>0</iyz>
          <izz>2.81486701762e-06</izz>
        </inertia>
      </inertial>
      <collision name="BRU_col">
        <pose>0 0 -0.035 0 0 0</pose>
        <geometry>
          <cylinder>
            <radius>0.004</radius>
            <length>0.07</length>
          </cylinder>
        </geometry>
      </collision>
      <visual name="BRU_vis">
        <pose>-0.0040 0 0 0 1.57079632679 0</pose>
        <geometry>
          <mesh>
            <uri>model://tigrillo/meshes/femur.dae</uri>
            <scale>0.001 0.001 0.001</scale>
          </mesh>
        </geometry>
        <material>
          <script>
            <uri>file://media/materials/scripts/gazebo.material</uri>
            <name>Gazebo/Turquoise</name>
          </script>
        </material>
      </visual>
    </link>
    <link name="BRD">
      <pose>0.0495 -0.0696945683501 0.0670006663495 0.590048866587 0 0</pose>
      <inertial>
        <pose>0 0 -0.01 0 0 0</pose>
        <mass>0.452389342117</mass>
        <inertia>
          <ixx>0.000307172363297</ixx>
          <ixy>0</ixy>
          <ixz>0</ixz>
          <iyy>0.000307172363297</iyy>
          <iyz>0</iyz>
          <izz>3.61911473694e-06</izz>
        </inertia>
      </inertial>
      <collision name="BRDT_col">
        <pose>0 0 -0.01 0 0 0</pose>
        <geometry>
          <cylinder>
            <radius>0.004</radius>
            <length>0.09</length>
          </cylinder>
        </geometry>
      </collision>
      <visual name="BRDT_vis">
        <pose>0.004 0 -0.048-1.57079632679 0 1.57079632679</pose>
        <geometry>
          <mesh>
            <uri>model://tigrillo/meshes/tibia.dae</uri>
            <scale>0.001 0.001 0.001</scale>
          </mesh>
        </geometry>
        <material>
          <script>
            <name>Gazebo/Turquoise</name>
            <uri>file://media/materials/scripts/gazebo.material</uri>
          </script>
        </material>
      </visual>
      <collision name="BRDF_col">
        <pose> 0 0 -0.055 0 0 0</pose>
        <geometry>
          <sphere>
            <radius>0.006</radius>
          </sphere>
        </geometry>
        <surface>
          <friction>
            <ode>
              <mu>15000</mu>
              <mu2>15000</mu2>
            </ode>
          </friction>
          <contact>
            <ode>
              <min_depth>0.0005</min_depth>
            </ode>
          </contact>
        </surface>
      </collision>
    </link>
    <joint name="body_front_J" type="fixed">
      <parent>body_middle</parent>
      <child>body_front</child>
    </joint>
    <joint name="body_hind_J" type="fixed">
      <parent>body_middle</parent>
      <child>body_hind</child>
    </joint>
    <joint name="BLMJ" type="fixed">
      <parent>body_hind</parent>
      <child>BLM</child>
    </joint>
    <joint name="BLUJ" type="revolute">
      <parent>BLM</parent>
      <child>BLU</child>
      <axis>
        <xyz>1 0 0</xyz>
        <limit>
          <lower>-1.57515964992</lower>
          <upper>1.56643300366</upper>
        </limit>
      </axis>
    </joint>
    <joint name="BLDJ" type="revolute">
      <parent>BLU</parent>
      <child>BLD</child>
      <axis>
        <xyz>1 0 0</xyz>
        <dynamics>
          <damping>0.08</damping>
          <spring_stiffness>0.590685684903</spring_stiffness>
        </dynamics>
        <limit>
          <lower>0.272951133413</lower>
          <upper>1.57079632679</upper>
        </limit>
      </axis>
    </joint>
    <joint name="FRMJ" type="fixed">
      <parent>body_front</parent>
      <child>FRM</child>
    </joint>
    <joint name="FRUJ" type="revolute">
      <parent>FRM</parent>
      <child>FRU</child>
      <axis>
        <xyz>1 0 0</xyz>
        <limit>
          <lower>-1.57515964992</lower>
          <upper>1.56643300366</upper>
        </limit>
      </axis>
    </joint>
    <joint name="FRDJ" type="revolute">
      <parent>FRU</parent>
      <child>FRD</child>
      <axis>
        <xyz>1 0 0</xyz>
        <dynamics>
          <damping>0.01</damping>
          <spring_stiffness>0.701804774142</spring_stiffness>
        </dynamics>
        <limit>
          <lower>0.394951133413</lower>
          <upper>1.57079632679</upper>
        </limit>
      </axis>
    </joint>
    <joint name="FLMJ" type="fixed">
      <parent>body_front</parent>
      <child>FLM</child>
    </joint>
    <joint name="FLUJ" type="revolute">
      <parent>FLM</parent>
      <child>FLU</child>
      <axis>
        <xyz>1 0 0</xyz>
        <limit>
          <lower>-1.57515964992</lower>
          <upper>1.56643300366</upper>
        </limit>
      </axis>
    </joint>
    <joint name="FLDJ" type="revolute">
      <parent>FLU</parent>
      <child>FLD</child>
      <axis>
        <xyz>1 0 0</xyz>
        <dynamics>
          <damping>0.01</damping>
          <spring_stiffness>0.350902387071</spring_stiffness>
        </dynamics>
        <limit>
          <lower>0.269951133413</lower>
          <upper>1.57079632679</upper>
        </limit>
      </axis>
    </joint>
    <joint name="BRMJ" type="fixed">
      <parent>body_hind</parent>
      <child>BRM</child>
    </joint>
    <joint name="BRUJ" type="revolute">
      <parent>BRM</parent>
      <child>BRU</child>
      <axis>
        <xyz>1 0 0</xyz>
        <limit>
          <lower>-1.57515964992</lower>
          <upper>1.56643300366</upper>
        </limit>
      </axis>
    </joint>
    <joint name="BRDJ" type="revolute">
      <parent>BRU</parent>
      <child>BRD</child>
      <axis>
        <xyz>1 0 0</xyz>
        <dynamics>
          <damping>0.12</damping>
          <spring_stiffness>0.649169416081</spring_stiffness>
        </dynamics>
        <limit>
          <lower>0.349951133413</lower>
          <upper>1.57079632679</upper>
        </limit>
      </axis>
    </joint>
    <plugin filename="libtigrillo_2_plugin.so" name="TigrilloPlugin">
      <p>50.0</p>
      <i>0.01</i>
      <d>0.01</d>
    </plugin>
    <plugin filename="libgazebo_ros_imu.so" name="ImuPlugin">
      <alwaysOn>true</alwaysOn>
      <bodyName>body_front</bodyName>
      <topicName>imu_data</topicName>
      <serviceName>imu_service</serviceName>
      <gaussianNoise>0.0</gaussianNoise>
      <updateRate>20.0</updateRate>
    </plugin>
  </model>
</sdf>
